[2024-03-15 15:57:49,986] {taskinstance.py:1032} INFO - Dependencies all met for <TaskInstance: dag_ml_life_cycle.get_gold_data scheduled__2024-03-15T20:50:39.055353+00:00 [queued]>
[2024-03-15 15:57:50,043] {taskinstance.py:1032} INFO - Dependencies all met for <TaskInstance: dag_ml_life_cycle.get_gold_data scheduled__2024-03-15T20:50:39.055353+00:00 [queued]>
[2024-03-15 15:57:50,043] {taskinstance.py:1238} INFO - 
--------------------------------------------------------------------------------
[2024-03-15 15:57:50,043] {taskinstance.py:1239} INFO - Starting attempt 4 of 4
[2024-03-15 15:57:50,043] {taskinstance.py:1240} INFO - 
--------------------------------------------------------------------------------
[2024-03-15 15:57:50,051] {taskinstance.py:1259} INFO - Executing <Task(PythonOperator): get_gold_data> on 2024-03-15 20:50:39.055353+00:00
[2024-03-15 15:57:50,057] {standard_task_runner.py:52} INFO - Started process 96730 to run task
[2024-03-15 15:57:50,063] {standard_task_runner.py:76} INFO - Running: ['airflow', 'tasks', 'run', 'dag_ml_life_cycle', 'get_gold_data', 'scheduled__2024-03-15T20:50:39.055353+00:00', '--job-id', '32', '--raw', '--subdir', 'DAGS_FOLDER/lifecycle_ml_example/dags/dag_ml_life_cycle.py', '--cfg-path', '/var/folders/t4/c2kdpvnj6r793w3k056dkc640000gp/T/tmper3y5svb', '--error-file', '/var/folders/t4/c2kdpvnj6r793w3k056dkc640000gp/T/tmp676dev4d']
[2024-03-15 15:57:50,066] {standard_task_runner.py:77} INFO - Job 32: Subtask get_gold_data
[2024-03-15 15:57:50,108] {logging_mixin.py:109} INFO - Running <TaskInstance: dag_ml_life_cycle.get_gold_data scheduled__2024-03-15T20:50:39.055353+00:00 [running]> on host 1.0.0.0.0.0.0.0.0.0.0.0.0.0.0.0.0.0.0.0.0.0.0.0.0.0.0.0.0.0.0.0.ip6.arpa
[2024-03-15 15:57:50,133] {taskinstance.py:1424} INFO - Exporting the following env vars:
AIRFLOW_CTX_DAG_OWNER=airflow
AIRFLOW_CTX_DAG_ID=dag_ml_life_cycle
AIRFLOW_CTX_TASK_ID=get_gold_data
AIRFLOW_CTX_EXECUTION_DATE=2024-03-15T20:50:39.055353+00:00
AIRFLOW_CTX_DAG_RUN_ID=scheduled__2024-03-15T20:50:39.055353+00:00
[2024-03-15 15:57:50,134] {data_preprocessing.py:33} INFO - Random error: 0.811458990363184
[2024-03-15 15:57:50,135] {taskinstance.py:1700} ERROR - Task failed with exception
Traceback (most recent call last):
  File "/Users/macbook/anaconda3/envs/airflow_env/lib/python3.9/site-packages/airflow/models/taskinstance.py", line 1329, in _run_raw_task
    self._execute_task_with_callbacks(context)
  File "/Users/macbook/anaconda3/envs/airflow_env/lib/python3.9/site-packages/airflow/models/taskinstance.py", line 1455, in _execute_task_with_callbacks
    result = self._execute_task(context, self.task)
  File "/Users/macbook/anaconda3/envs/airflow_env/lib/python3.9/site-packages/airflow/models/taskinstance.py", line 1511, in _execute_task
    result = execute_callable(context=context)
  File "/Users/macbook/anaconda3/envs/airflow_env/lib/python3.9/site-packages/airflow/operators/python.py", line 174, in execute
    return_value = self.execute_callable()
  File "/Users/macbook/anaconda3/envs/airflow_env/lib/python3.9/site-packages/airflow/operators/python.py", line 185, in execute_callable
    return self.python_callable(*self.op_args, **self.op_kwargs)
  File "/Users/macbook/Desktop/airflow_tutorial/airflow/dags/lifecycle_ml_example/src/features/data_preprocessing.py", line 35, in get_gold_data
    raise ValueError("Random error")
ValueError: Random error
[2024-03-15 15:57:50,143] {taskinstance.py:1267} INFO - Marking task as FAILED. dag_id=dag_ml_life_cycle, task_id=get_gold_data, execution_date=20240315T205039, start_date=20240315T205749, end_date=20240315T205750
[2024-03-15 15:57:50,149] {standard_task_runner.py:89} ERROR - Failed to execute job 32 for task get_gold_data
Traceback (most recent call last):
  File "/Users/macbook/anaconda3/envs/airflow_env/lib/python3.9/site-packages/airflow/task/task_runner/standard_task_runner.py", line 85, in _start_by_fork
    args.func(args, dag=self.dag)
  File "/Users/macbook/anaconda3/envs/airflow_env/lib/python3.9/site-packages/airflow/cli/cli_parser.py", line 48, in command
    return func(*args, **kwargs)
  File "/Users/macbook/anaconda3/envs/airflow_env/lib/python3.9/site-packages/airflow/utils/cli.py", line 92, in wrapper
    return f(*args, **kwargs)
  File "/Users/macbook/anaconda3/envs/airflow_env/lib/python3.9/site-packages/airflow/cli/commands/task_command.py", line 298, in task_run
    _run_task_by_selected_method(args, dag, ti)
  File "/Users/macbook/anaconda3/envs/airflow_env/lib/python3.9/site-packages/airflow/cli/commands/task_command.py", line 107, in _run_task_by_selected_method
    _run_raw_task(args, ti)
  File "/Users/macbook/anaconda3/envs/airflow_env/lib/python3.9/site-packages/airflow/cli/commands/task_command.py", line 180, in _run_raw_task
    ti._run_raw_task(
  File "/Users/macbook/anaconda3/envs/airflow_env/lib/python3.9/site-packages/airflow/utils/session.py", line 70, in wrapper
    return func(*args, session=session, **kwargs)
  File "/Users/macbook/anaconda3/envs/airflow_env/lib/python3.9/site-packages/airflow/models/taskinstance.py", line 1329, in _run_raw_task
    self._execute_task_with_callbacks(context)
  File "/Users/macbook/anaconda3/envs/airflow_env/lib/python3.9/site-packages/airflow/models/taskinstance.py", line 1455, in _execute_task_with_callbacks
    result = self._execute_task(context, self.task)
  File "/Users/macbook/anaconda3/envs/airflow_env/lib/python3.9/site-packages/airflow/models/taskinstance.py", line 1511, in _execute_task
    result = execute_callable(context=context)
  File "/Users/macbook/anaconda3/envs/airflow_env/lib/python3.9/site-packages/airflow/operators/python.py", line 174, in execute
    return_value = self.execute_callable()
  File "/Users/macbook/anaconda3/envs/airflow_env/lib/python3.9/site-packages/airflow/operators/python.py", line 185, in execute_callable
    return self.python_callable(*self.op_args, **self.op_kwargs)
  File "/Users/macbook/Desktop/airflow_tutorial/airflow/dags/lifecycle_ml_example/src/features/data_preprocessing.py", line 35, in get_gold_data
    raise ValueError("Random error")
ValueError: Random error
[2024-03-15 15:57:50,160] {local_task_job.py:154} INFO - Task exited with return code 1
[2024-03-15 15:57:50,180] {local_task_job.py:264} INFO - 0 downstream tasks scheduled from follow-on schedule check
