[2024-03-18 15:55:51,292] {taskinstance.py:1032} INFO - Dependencies all met for <TaskInstance: dag_ml_life_cycle.get_gold_data scheduled__2024-03-18T15:45:47.382372+00:00 [queued]>
[2024-03-18 15:55:51,439] {taskinstance.py:1032} INFO - Dependencies all met for <TaskInstance: dag_ml_life_cycle.get_gold_data scheduled__2024-03-18T15:45:47.382372+00:00 [queued]>
[2024-03-18 15:55:51,440] {taskinstance.py:1238} INFO - 
--------------------------------------------------------------------------------
[2024-03-18 15:55:51,440] {taskinstance.py:1239} INFO - Starting attempt 1 of 4
[2024-03-18 15:55:51,440] {taskinstance.py:1240} INFO - 
--------------------------------------------------------------------------------
[2024-03-18 15:55:51,460] {taskinstance.py:1259} INFO - Executing <Task(PythonOperator): get_gold_data> on 2024-03-18 15:45:47.382372+00:00
[2024-03-18 15:55:51,477] {standard_task_runner.py:52} INFO - Started process 57438 to run task
[2024-03-18 15:55:51,496] {standard_task_runner.py:76} INFO - Running: ['airflow', 'tasks', 'run', 'dag_ml_life_cycle', 'get_gold_data', 'scheduled__2024-03-18T15:45:47.382372+00:00', '--job-id', '37', '--raw', '--subdir', 'DAGS_FOLDER/lifecycle_ml_example/dags/dag_ml_life_cycle.py', '--cfg-path', '/var/folders/t4/c2kdpvnj6r793w3k056dkc640000gp/T/tmp9r2wcs0h', '--error-file', '/var/folders/t4/c2kdpvnj6r793w3k056dkc640000gp/T/tmpmbtoqnic']
[2024-03-18 15:55:51,503] {standard_task_runner.py:77} INFO - Job 37: Subtask get_gold_data
[2024-03-18 15:55:51,639] {logging_mixin.py:109} INFO - Running <TaskInstance: dag_ml_life_cycle.get_gold_data scheduled__2024-03-18T15:45:47.382372+00:00 [running]> on host macbook-pro-2.local
[2024-03-18 15:55:51,733] {taskinstance.py:1424} INFO - Exporting the following env vars:
AIRFLOW_CTX_DAG_OWNER=airflow
AIRFLOW_CTX_DAG_ID=dag_ml_life_cycle
AIRFLOW_CTX_TASK_ID=get_gold_data
AIRFLOW_CTX_EXECUTION_DATE=2024-03-18T15:45:47.382372+00:00
AIRFLOW_CTX_DAG_RUN_ID=scheduled__2024-03-18T15:45:47.382372+00:00
[2024-03-18 15:55:51,738] {data_preprocessing.py:34} INFO - Random error: 0.4516978083288522
[2024-03-18 15:55:51,739] {taskinstance.py:1700} ERROR - Task failed with exception
Traceback (most recent call last):
  File "/Users/macbook/anaconda3/envs/airflow_env/lib/python3.9/site-packages/airflow/models/taskinstance.py", line 1329, in _run_raw_task
    self._execute_task_with_callbacks(context)
  File "/Users/macbook/anaconda3/envs/airflow_env/lib/python3.9/site-packages/airflow/models/taskinstance.py", line 1455, in _execute_task_with_callbacks
    result = self._execute_task(context, self.task)
  File "/Users/macbook/anaconda3/envs/airflow_env/lib/python3.9/site-packages/airflow/models/taskinstance.py", line 1511, in _execute_task
    result = execute_callable(context=context)
  File "/Users/macbook/anaconda3/envs/airflow_env/lib/python3.9/site-packages/airflow/operators/python.py", line 174, in execute
    return_value = self.execute_callable()
  File "/Users/macbook/anaconda3/envs/airflow_env/lib/python3.9/site-packages/airflow/operators/python.py", line 185, in execute_callable
    return self.python_callable(*self.op_args, **self.op_kwargs)
  File "/Users/macbook/Desktop/airflow_tutorial/airflow/dags/lifecycle_ml_example/src/features/data_preprocessing.py", line 36, in get_gold_data
    raise ValueError("Random error")
ValueError: Random error
[2024-03-18 15:55:51,758] {taskinstance.py:1267} INFO - Marking task as UP_FOR_RETRY. dag_id=dag_ml_life_cycle, task_id=get_gold_data, execution_date=20240318T154547, start_date=20240318T205551, end_date=20240318T205551
[2024-03-18 15:55:51,780] {standard_task_runner.py:89} ERROR - Failed to execute job 37 for task get_gold_data
Traceback (most recent call last):
  File "/Users/macbook/anaconda3/envs/airflow_env/lib/python3.9/site-packages/airflow/task/task_runner/standard_task_runner.py", line 85, in _start_by_fork
    args.func(args, dag=self.dag)
  File "/Users/macbook/anaconda3/envs/airflow_env/lib/python3.9/site-packages/airflow/cli/cli_parser.py", line 48, in command
    return func(*args, **kwargs)
  File "/Users/macbook/anaconda3/envs/airflow_env/lib/python3.9/site-packages/airflow/utils/cli.py", line 92, in wrapper
    return f(*args, **kwargs)
  File "/Users/macbook/anaconda3/envs/airflow_env/lib/python3.9/site-packages/airflow/cli/commands/task_command.py", line 298, in task_run
    _run_task_by_selected_method(args, dag, ti)
  File "/Users/macbook/anaconda3/envs/airflow_env/lib/python3.9/site-packages/airflow/cli/commands/task_command.py", line 107, in _run_task_by_selected_method
    _run_raw_task(args, ti)
  File "/Users/macbook/anaconda3/envs/airflow_env/lib/python3.9/site-packages/airflow/cli/commands/task_command.py", line 180, in _run_raw_task
    ti._run_raw_task(
  File "/Users/macbook/anaconda3/envs/airflow_env/lib/python3.9/site-packages/airflow/utils/session.py", line 70, in wrapper
    return func(*args, session=session, **kwargs)
  File "/Users/macbook/anaconda3/envs/airflow_env/lib/python3.9/site-packages/airflow/models/taskinstance.py", line 1329, in _run_raw_task
    self._execute_task_with_callbacks(context)
  File "/Users/macbook/anaconda3/envs/airflow_env/lib/python3.9/site-packages/airflow/models/taskinstance.py", line 1455, in _execute_task_with_callbacks
    result = self._execute_task(context, self.task)
  File "/Users/macbook/anaconda3/envs/airflow_env/lib/python3.9/site-packages/airflow/models/taskinstance.py", line 1511, in _execute_task
    result = execute_callable(context=context)
  File "/Users/macbook/anaconda3/envs/airflow_env/lib/python3.9/site-packages/airflow/operators/python.py", line 174, in execute
    return_value = self.execute_callable()
  File "/Users/macbook/anaconda3/envs/airflow_env/lib/python3.9/site-packages/airflow/operators/python.py", line 185, in execute_callable
    return self.python_callable(*self.op_args, **self.op_kwargs)
  File "/Users/macbook/Desktop/airflow_tutorial/airflow/dags/lifecycle_ml_example/src/features/data_preprocessing.py", line 36, in get_gold_data
    raise ValueError("Random error")
ValueError: Random error
[2024-03-18 15:55:51,806] {local_task_job.py:154} INFO - Task exited with return code 1
[2024-03-18 15:55:51,880] {local_task_job.py:264} INFO - 0 downstream tasks scheduled from follow-on schedule check
